Workbook

Sheet ALGN(IS)
A2: Align Technology Inc (ALGN US) - Adjusted
A4: In Millions of USD except Per Share | C4: FY 2007 | D4: FY 2008 | E4: FY 2009 | F4: FY 2010 | G4: FY 2011 | H4: FY 2012 | I4: FY 2013 | J4: FY 2014 | K4: FY 2015 | T4: Last 12M | U4: FY 2016 Est | V4: FY 2017 Est
A5: 12 Months Ending | C5: 12/31/2007 | D5: 12/31/2008 | E5: 12/31/2009 | F5: 12/31/2010 | G5: 12/31/2011 | H5: 12/31/2012 | I5: 12/31/2013 | J5: 12/31/2014 | K5: 12/31/2015 | L5: 2016 | M5: 2017 | N5: 2018 | O5: 2019 | P5: 2020 | Q5: CAGR | R5: AVG | T5: 09/30/2016 | U5: 12/31/2016 | V5: 12/31/2017
A6: Revenue | B6: SALES_REV_TURN | C6: 284.332 | D6: 303.976 | E6: 312.333 | F6: 387.126 | G6: 479.741 | H6: 560.041 | I6: 660.206 | J6: 761.653 | K6: 845.486 | L6: =K6*(1+L7) -> 972.3089 | M6: =L6*(1+M7) -> 1118.1552 | N6: =M6*(1+N7) -> 1252.3339 | O6: =N6*(1+O7) -> 1377.5672 | P6: =O6*(1+P7) -> 1515.324 | T6: 1016.947 | U6: 1078.538 | V6: 1286.154
A7: %yoy | D7: =(D6-C6)/C6 -> 0.069088249 | E7: =(E6-D6)/D6 -> 0.027492302 | F7: =(F6-E6)/E6 -> 0.23946557 | G7: =(G6-F6)/F6 -> 0.23923735 | H7: =(H6-G6)/G6 -> 0.16738198 | I7: =(I6-H6)/H6 -> 0.17885298 | J7: =(J6-I6)/I6 -> 0.15365962 | K7: =(K6-J6)/J6 -> 0.11006718 | L7: 0.15 | M7: 0.15 | N7: 0.12 | O7: 0.1 | P7: 0.1 | Q7: =(K6/G6)^(1/5)-1 -> 0.12000489 | R7: =AVERAGE(G7:K7) -> 0.16983982
A8: + Sales & Services Revenue | B8: IS_SALES_AND_SERVICES_REVENUES | C8: — | D8: — | E8: 312.333 | F8: 387.126 | G8: 479.741 | H8: 560.041 | I8: 660.206 | J8: 761.653 | K8: 845.486 | T8: 1016.947
A9: - Cost of Revenue | B9: IS_COGS_TO_FE_AND_PP_AND_G | C9: 75.035 | D9: 78.85 | E9: 78.841 | F9: 83.709 | G9: 117.306 | H9: 142.918 | I9: 162.1 | J9: 183.21 | K9: 205.376 | L9: =L$6*L10 -> 233.35414 | M9: =M$6*M10 -> 268.35726 | N9: =N$6*N10 -> 300.56013 | O9: =O$6*O10 -> 330.61614 | P9: =P$6*P10 -> 363.67775 | T9: 249.092
A10: % reveneue | C10: =C9/C$6 -> 0.26389924 | D10: =D9/D$6 -> 0.25939548 | E10: =E9/E$6 -> 0.2524261 | F10: =F9/F$6 -> 0.21623192 | G10: =G9/G$6 -> 0.24451944 | H10: =H9/H$6 -> 0.25519203 | I10: =I9/I$6 -> 0.24552943 | J10: =J9/J$6 -> 0.24054261 | K10: =K9/K$6 -> 0.24290881 | L10: 0.24 | M10: 0.24 | N10: 0.24 | O10: 0.24 | P10: 0.24 | Q10: =(K9/G9)^(1/5)-1 -> 0.11852551 | R10: =AVERAGE(G10:K10) -> 0.24573846
A11: + Cost of Goods & Services | B11: IS_COG_AND_SERVICES_SOLD | C11: — | D11: — | E11: 78.841 | F11: 83.709 | G11: 117.306 | H11: 142.918 | I11: 162.1 | J11: 183.21 | K11: 205.376 | T11: 249.092
A12: Gross Profit | B12: GROSS_PROFIT | C12: 209.297 | D12: 225.126 | E12: 233.492 | F12: 303.417 | G12: 362.435 | H12: 417.123 | I12: 498.106 | J12: 578.443 | K12: 640.11 | L12: =L6-L9 -> 738.95476 | M12: =M6-M9 -> 849.79798 | N12: =N6-N9 -> 951.77374 | O12: =O6-O9 -> 1046.9511 | P12: =P6-P9 -> 1151.6462 | T12: 767.855 | U12: 814.56582 | V12: 972.49962
A13: + Other Operating Income | B13: IS_OTHER_OPER_INC | C13: — | D13: — | E13: 0 | F13: 0 | G13: 0 | H13: 0 | I13: 0 | J13: 0 | K13: 0 | T13: 0
A14: - Operating Expenses | B14: IS_OPERATING_EXPN | C14: 177.238 | D14: 203.381 | E14: 196.512 | F14: 204.8 | G14: 260.963 | H14: 292.889 | I14: 336.881 | J14: 384.867 | K14: 451.476 | L14: =SUM(L15,L19,L21,L23) -> 508.0314 | M14: =SUM(M15,M19,M21,M23) -> 584.23611 | N14: =SUM(N15,N19,N21,N23) -> 654.34444 | O14: =SUM(O15,O19,O21,O23) -> 719.77889 | P14: =SUM(P15,P19,P21,P23) -> 791.75678 | T14: 527.967
A15: + Selling, General & Admin | B15: IS_SG&A_EXPENSE | C15: 151.511 | D15: 177.216 | E15: 174.26 | F15: 178.803 | G15: 221.694 | H15: 247.881 | I15: 292.798 | J15: 332.068 | K15: 390.239 | L15: =L$6*L16 -> 437.539 | M15: =M$6*M16 -> 503.16986 | N15: =N$6*N16 -> 563.55024 | O15: =O$6*O16 -> 619.90526 | P15: =P$6*P16 -> 681.89579 | T15: 459.967
A16: % reveneue | C16: =C15/C$6 -> 0.53286651 | D16: =D15/D$6 -> 0.58299339 | E16: =E15/E$6 -> 0.55793016 | F16: =F15/F$6 -> 0.46187288 | G16: =G15/G$6 -> 0.46211185 | H16: =H15/H$6 -> 0.44261224 | I16: =I15/I$6 -> 0.44349491 | J16: =J15/J$6 -> 0.43598332 | K16: =K15/K$6 -> 0.46155584 | L16: 0.45 | M16: 0.45 | N16: 0.45 | O16: 0.45 | P16: 0.45 | Q16: =(K15/G15)^(1/5)-1 -> 0.11973524 | R16: =AVERAGE(G16:K16) -> 0.44915163
A17: + Selling & Marketing | B17: IS_SELLING_EXPENSES | C17: 98.231 | D17: 115.062 | E17: 112.542 | F17: 114.013 | G17: 142.174 | H17: 152.041 | I17: 180.046 | J17: 217.262 | K17: —
A18: + General & Administrative | B18: IS_GENERAL_AND_ADMINISTRATIVE | C18: — | D18: — | E18: 61.718 | F18: 64.79 | G18: 79.52 | H18: 95.84 | I18: 112.752 | J18: 114.806 | K18: —
A19: + Research & Development | B19: IS_OPEX_R&D | C19: — | D19: — | E19: 22.252 | F19: 25.997 | G19: 37.154 | H19: 42.869 | I19: 44.083 | J19: 52.799 | K19: 61.237 | L19: =L$6*L20 -> 70.492395 | M19: =M$6*M20 -> 81.066255 | N19: =N$6*N20 -> 90.794205 | O19: =O$6*O20 -> 99.873626 | P19: =P$6*P20 -> 109.86099 | T19: 68
A20: % reveneue | C20: =C19/C$6 -> #VALUE! | D20: =D19/D$6 -> #VALUE! | E20: =E19/E$6 -> 0.071244473 | F20: =F19/F$6 -> 0.067153847 | G20: =G19/G$6 -> 0.077445955 | H20: =H19/H$6 -> 0.076546181 | I20: =I19/I$6 -> 0.066771583 | J20: =J19/J$6 -> 0.069321594 | K20: =K19/K$6 -> 0.072428166 | L20: 0.0725 | M20: 0.0725 | N20: 0.0725 | O20: 0.0725 | P20: 0.0725 | Q20: =(K19/G19)^(1/5)-1 -> 0.10510022 | R20: =AVERAGE(G20:K20) -> 0.072502696
A21: + Depreciation & Amortization | B21: IS_DEPRECIATION_AND_AMORTIZATION | C21: — | D21: — | E21: — | F21: — | G21: 2.443 | H21: 3.455 | I21: — | J21: — | K21: — | L21: =L$6*L22 -> 0 | M21: =M$6*M22 -> 0 | N21: =N$6*N22 -> 0 | O21: =O$6*O22 -> 0 | P21: =P$6*P22 -> 0
A22: % reveneue | C22: =C21/C$6 -> #VALUE! | D22: =D21/D$6 -> #VALUE! | E22: =E21/E$6 -> #VALUE! | F22: =F21/F$6 -> #VALUE! | G22: =G21/G$6 -> 0.0050923311 | H22: =H21/H$6 -> 0.0061691912 | I22: =I21/I$6 -> #VALUE! | J22: =J21/J$6 -> #VALUE! | K22: =K21/K$6 -> #VALUE! | L22: 0 | M22: 0 | N22: 0 | O22: 0 | P22: 0 | Q22: =(K21/G21)^(1/5)-1 -> #VALUE! | R22: =AVERAGE(G22:K22) -> #VALUE!
A23: + Other Operating Expense | B23: IS_OTHER_OPERATING_EXPENSES | C23: — | D23: — | E23: 0 | F23: 0 | G23: -0.328 | H23: -1.316 | I23: 0 | J23: 0 | K23: 0 | L23: =L$6*L24 -> 0 | M23: =M$6*M24 -> 0 | N23: =N$6*N24 -> 0 | O23: =O$6*O24 -> 0 | P23: =P$6*P24 -> 0 | T23: 0
A24: % reveneue | C24: =C23/C$6 -> #VALUE! | D24: =D23/D$6 -> #VALUE! | E24: =E23/E$6 -> 0 | F24: =F23/F$6 -> 0 | G24: =G23/G$6 -> -0.00068370225 | H24: =H23/H$6 -> -0.002349828 | I24: =I23/I$6 -> 0 | J24: =J23/J$6 -> 0 | K24: =K23/K$6 -> 0 | L24: 0 | M24: 0 | N24: 0 | O24: 0 | P24: 0 | Q24: =(K23/G23)^(1/5)-1 -> -1 | R24: =AVERAGE(G24:K24) -> -0.00060670604
A25: Operating Income (Loss) | B25: IS_OPER_INC | C25: 32.059 | D25: 21.745 | E25: 36.98 | F25: 98.617 | G25: 101.472 | H25: 124.234 | I25: 161.225 | J25: 193.576 | K25: 188.634 | L25: =L12-L14 -> 230.92336 | M25: =M12-M14 -> 265.56187 | N25: =N12-N14 -> 297.42929 | O25: =O12-O14 -> 327.17222 | P25: =P12-P14 -> 359.88944 | T25: 239.888 | U25: 249.5 | V25: 312.583
A26: - Non-Operating (Income) Loss | B26: IS_NONOP_INCOME_LOSS | C26: — | D26: — | E26: -0.119 | F26: 0.731 | G26: 0.419 | H26: 1.296 | I26: 1.073 | J26: 3.207 | K26: 2.533 | T26: -1.474
A27: + Interest Expense, Net | B27: IS_NET_INTEREST_EXPENSE | C27: -3.853 | D27: -3.028 | E27: -0.494 | F27: -0.536 | G27: -0.501 | H27: — | I27: — | J27: — | K27: —
A28: + Interest Expense | B28: IS_INT_EXPENSE | C28: 0.342 | D28: 0.024 | E28: 0.085 | F28: 0.019 | G28: 0.051 | H28: — | I28: — | J28: — | K28: —
A29: - Interest Income | B29: IS_INT_INC | C29: 4.195 | D29: 3.052 | E29: 0.579 | F29: 0.555 | G29: 0.552 | H29: 0.757 | I29: — | J29: — | K29: —
A30: + Foreign Exch (Gain) Loss | B30: IS_FOREIGN_EXCH_LOSS | C30: 0 | D30: 0 | E30: 0 | F30: 0 | G30: 0 | H30: 0 | I30: 0 | J30: 0 | K30: 0
A31: + (Income) Loss from Affiliates | B31: INCOME_LOSS_FROM_AFFILIATES | C31: — | D31: — | E31: 0 | F31: 0 | G31: 0 | H31: 0 | I31: 0 | J31: 0 | K31: 0
A32: + Other Non-Op (Income) Loss | B32: IS_OTHER_NON_OPERATING_INC_LOSS | C32: — | D32: — | E32: 0.375 | F32: 1.267 | G32: 0.92 | H32: 2.053 | I32: 1.073 | J32: 3.207 | K32: 2.533 | T32: -1.474
A33: Pretax Income (Loss), Adjusted | B33: PRETAX_INC | C33: 36.95 | D33: 17.076 | E33: 37.099 | F33: 97.886 | G33: 101.053 | H33: 122.938 | I33: 160.152 | J33: 190.369 | K33: 186.101 | T33: 241.362 | U33: 251.889 | V33: 317.889
A34: - Abnormal Losses (Gains) | B34: IS_ABNORMAL_ITEM | C34: -1.796 | D34: -58.377 | E34: 70.992 | F34: -4.117 | G34: 11.112 | H34: 38.642 | I34: 67.013 | J34: 0 | K34: 0 | T34: 0
A35: + Merger/Acquisition Expense | B35: IS_MERGER_ACQUISITION_EXPENSE | C35: — | D35: — | E35: — | F35: — | G35: 10.03 | H35: 1.271 | I35: — | J35: — | K35: —
A36: + Asset Write-Down | B36: IS_IMPAIRMENT_ASSETS | C36: — | D36: — | E36: — | F36: — | G36: — | H36: — | I36: 26.32 | J36: — | K36: —
A37: + Impairment of Goodwill | B37: IS_IMPAIRMENT_GOODWILL_INTANGIBL | C37: — | D37: — | E37: — | F37: — | G37: — | H37: 36.591 | I37: 40.693 | J37: — | K37: —
A38: + Legal Settlement | B38: IS_LEGAL_LITIGATION_SETTLEMENT | C38: — | D38: — | E38: 69.673 | F38: 4.549 | G38: — | H38: — | I38: — | J38: — | K38: —
A39: + Restructuring | B39: IS_RESTRUCTURING_EXPENSES | C39: — | D39: — | E39: 1.319 | F39: — | G39: 1.082 | H39: 0.78 | I39: — | J39: — | K39: —
A40: + Insurance Settlement | B40: IS_INSURANCE_SETTLEMENTS | C40: — | D40: — | E40: — | F40: -8.666 | G40: — | H40: — | I40: — | J40: — | K40: —
A41: Pretax Income (Loss), GAAP | B41: PRETAX_INC | C41: 36.95 | D41: 17.076 | E41: -33.893 | F41: 102.003 | G41: 89.941 | H41: 84.296 | I41: 93.139 | J41: 190.369 | K41: 186.101 | T41: 241.362 | U41: 251.889 | V41: 317.889
A42: - Income Tax Expense (Benefit) | B42: IS_INC_TAX_EXP | C42: 1.226 | D42: -62.911 | E42: -2.624 | F42: 27.75 | G42: 23.225 | H42: 25.605 | I42: 28.844 | J42: 44.537 | K42: 42.081 | T42: 49.947
...

Sheet ALGN(BS_Annual)
A2: Align Technology Inc (ALGN US) - Standardized
A4: In Millions of USD except Per Share | C4: FY 2007 | D4: FY 2008 | E4: FY 2009 | F4: FY 2010 | G4: FY 2011 | H4: FY 2012 | I4: FY 2013 | J4: FY 2014 | K4: FY 2015
A5: 12 Months Ending | C5: 12/31/2007 | D5: 12/31/2008 | E5: 12/31/2009 | F5: 12/31/2010 | G5: 12/31/2011 | H5: 12/31/2012 | I5: 12/31/2013 | J5: 12/31/2014 | K5: 12/31/2015
A6: Total Assets
A7: + Cash, Cash Equivalents & STI | B7: C&CE_AND_STI_DETAILED | C7: 127.89 | D7: 110.166 | E7: 186.465 | F7: 303.279 | G7: 248.07 | H7: 334.871 | I7: 369.993 | J7: 454.658 | K7: 527.295
A8: + Cash & Cash Equivalents | B8: BS_CASH_NEAR_CASH_ITEM | C8: 89.119 | D8: 87.1 | E8: 166.487 | F8: 294.664 | G8: 240.675 | H8: 306.386 | I8: 242.953 | J8: 199.871 | K8: 167.714
A9: + ST Investments | B9: BS_MKT_SEC_OTHER_ST_INVEST | C9: 38.771 | D9: 23.066 | E9: 19.978 | F9: 8.615 | G9: 7.395 | H9: 28.485 | I9: 127.04 | J9: 254.787 | K9: 359.581
A10: + Accounts & Notes Receiv | B10: BS_ACCT_NOTE_RCV | C10: 44.85 | D10: 52.362 | E10: 54.537 | F10: 65.43 | G10: 91.537 | H10: 98.992 | I10: 113.25 | J10: 129.751 | K10: 158.55
A11: + Accounts Receivable, Net | B11: BS_ACCTS_REC_EXCL_NOTES_REC | C11: 44.85 | D11: 52.362 | E11: 54.537 | F11: 65.43 | G11: 91.537 | H11: 98.992 | I11: 113.25 | J11: 129.751 | K11: 158.55
A12: + Notes Receivable, Net | B12: NOTES_RECEIVABLE | C12: — | D12: — | E12: 0 | F12: 0 | G12: 0 | H12: 0 | I12: 0 | J12: 0 | K12: 0
A13: + Inventories | B13: BS_INVENTORIES | C13: 2.91 | D13: 1.965 | E13: 2.046 | F13: 2.544 | G13: 9.402 | H13: 15.122 | I13: 13.968 | J13: 15.928 | K13: 19.465
A14: + Raw Materials | B14: INVTRY_RAW_MATERIALS | C14: 1.983 | D14: 1.066 | E14: 1.079 | F14: 1.272 | G14: 4.542 | H14: 7.629 | I14: 5.172 | J14: 8.143 | K14: 9.95
A15: + Work In Process | B15: INVTRY_IN_PROGRESS | C15: 0.631 | D15: 0.416 | E15: 0.46 | F15: 1.03 | G15: 2.486 | H15: 3.889 | I15: 4.241 | J15: 2.97 | K15: 7.067
A16: + Finished Goods | B16: INVTRY_FINISHED_GOODS | C16: 0.296 | D16: 0.483 | E16: 0.507 | F16: 0.242 | G16: 2.374 | H16: 3.604 | I16: 4.555 | J16: 4.815 | K16: 2.448
A17: + Other Inventory | B17: BS_OTHER_INV | C17: 0 | D17: 0 | E17: 0 | F17: 0 | G17: 0 | H17: 0 | I17: 0 | J17: 0 | K17: 0
A18: + Other ST Assets | B18: OTHER_CURRENT_ASSETS_DETAILED | C18: 8.867 | D18: 13.414 | E18: 18.251 | F18: 17.358 | G18: 35.807 | H18: 36.808 | I18: 47.465 | J18: 56.823 | K18: 26.7
A19: + Derivative & Hedging Assets | B19: BS_DERIV_&_HEDGING_ASSETS_ST | C19: — | D19: — | E19: 0 | F19: 0 | G19: 0 | H19: 0 | I19: 0 | J19: 0 | K19: 0
A20: + Deferred Tax Assets | B20: BS_DEFERRED_TAX_ASSETS_ST | C20: — | D20: — | E20: — | F20: — | G20: — | H20: — | I20: — | J20: 37.053 | K20: 0
A21: + Misc ST Assets | B21: BS_OTHER_CUR_ASSET_LESS_PREPAY | C21: — | D21: — | E21: 18.251 | F21: 17.358 | G21: 35.807 | H21: 36.808 | I21: 47.465 | J21: 19.77 | K21: 26.7
A22: Total Current Assets | B22: BS_CUR_ASSET_REPORT | C22: 184.517 | D22: 177.907 | E22: 261.299 | F22: 388.611 | G22: 384.816 | H22: 485.793 | I22: 544.676 | J22: 657.16 | K22: 732.01
A23: + Property, Plant & Equip, Net | B23: BS_NET_FIX_ASSET | C23: 25.32 | D23: 26.979 | E23: 24.971 | F23: 30.684 | G23: 53.965 | H23: 79.191 | I23: 75.743 | J23: 90.125 | K23: 136.473
A24: + Property, Plant & Equip | B24: BS_GROSS_FIX_ASSET | C24: 79.079 | D24: 88.342 | E24: 94.977 | F24: 98.458 | G24: 129.432 | H24: 165.126 | I24: 181.249 | J24: 197.927 | K24: 254.51
A25: - Accumulated Depreciation | B25: BS_ACCUM_DEPR | C25: 53.759 | D25: 61.363 | E25: 70.006 | F25: 67.774 | G25: 75.467 | H25: 85.935 | I25: 105.506 | J25: 107.802 | K25: 118.037
A26: + LT Investments & Receivables | B26: BS_LT_INVEST | C26: 0 | D26: 0 | E26: 0 | F26: 9.089 | G26: 0 | H26: 21.252 | I26: 101.978 | J26: 147.892 | K26: 151.37
A27: + LT Marketable Securities | B27: BS_LT_MARKETABLE_SECURITIES | C27: — | D27: — | E27: — | F27: 9.089 | G27: — | H27: 21.252 | I27: 101.978 | J27: 147.892 | K27: 151.37
A28: + Other LT Assets | B28: BS_OTHER_ASSETS_DEF_CHRG_OTHER | C28: 12.924 | D28: 74.455 | E28: 68.97 | F28: 48.559 | G28: 210.483 | H28: 170.076 | I28: 109.75 | J28: 92.82 | K28: 138.78
A29: + Total Intangible Assets | B29: BS_DISCLOSED_INTANGIBLES | C29: 11.093 | D29: 8.266 | E29: 5.466 | F29: 2.666 | G29: 185.405 | H29: 145.013 | I29: 85.362 | J29: 82.056 | K29: 79.162
A30: + Goodwill | B30: BS_GOODWILL | C30: 0.478 | D30: 0.478 | E30: 0.478 | F30: 0.478 | G30: 135.383 | H30: 99.236 | I30: 61.623 | J30: 61.369 | K30: 61.074
A31: + Other Intangible Assets | B31: OTHER_INTANGIBLE_ASSETS_DETAILED | C31: 10.615 | D31: 7.788 | E31: 4.988 | F31: 2.188 | G31: 50.022 | H31: 45.777 | I31: 23.739 | J31: 20.687 | K31: 18.088
A32: + Deferred Tax Assets | B32: BS_DEFERRED_TAX_ASSETS_LT | C32: — | D32: — | E32: 61.535 | F32: 42.439 | G32: 22.337 | H32: 21.609 | I32: 15.766 | J32: 3.099 | K32: 51.416
A33: + Derivative & Hedging Assets | B33: BS_DERIV_&_HEDGING_ASSETS_LT | C33: — | D33: — | E33: 0 | F33: 0 | G33: 0 | H33: 0 | I33: 0 | J33: 0 | K33: 0
A34: + Misc LT Assets | B34: OTHER_NONCURRENT_ASSETS_DETAILED | C34: 1.831 | D34: 66.189 | E34: 1.969 | F34: 3.454 | G34: 2.741 | H34: 3.454 | I34: 8.622 | J34: 7.665 | K34: 8.202
A35: Total Noncurrent Assets | B35: BS_TOT_NON_CUR_ASSET | C35: 38.244 | D35: 101.434 | E35: 93.941 | F35: 88.332 | G35: 264.448 | H35: 270.519 | I35: 287.471 | J35: 330.837 | K35: 426.623
A36: Total Assets | B36: BS_TOT_ASSET | C36: 222.761 | D36: 279.341 | E36: 355.24 | F36: 476.943 | G36: 649.264 | H36: 756.312 | I36: 832.147 | J36: 987.997 | K36: 1158.633
A38: Liabilities & Shareholders' Equity
A39: + Payables & Accruals | B39: ACCT_PAYABLE_&_ACCRUALS_DETAILED | C39: 9.222 | D39: 5.58 | E39: 48.944 | F39: 59.126 | G39: 95.865 | H39: 93.796 | I39: 98.063 | J39: 111.127 | K39: 142.119
A40: + Accounts Payable | B40: BS_ACCT_PAYABLE | C40: 9.222 | D40: 5.58 | E40: 6.122 | F40: 7.768 | G40: 19.265 | H40: 19.549 | I40: 17.718 | J40: 23.247 | K40: 34.354
A41: + Accrued Taxes | B41: BS_TAXES_PAYABLE | C41: — | D41: — | E41: 2.92 | F41: 1.936 | G41: 0.426 | H41: 0 | I41: 0 | J41: 0 | K41: 2.646
A42: + Interest & Dividends Payable | B42: BS_INTEREST_&_DIVIDENDS_PAYABLE | C42: — | D42: — | E42: 0 | F42: 0 | G42: 0 | H42: 0 | I42: 0 | J42: 0 | K42: 0
A43: + Other Payables & Accruals | B43: BS_ACCRUAL | C43: — | D43: — | E43: 39.902 | F43: 49.422 | G43: 76.174 | H43: 74.247 | I43: 80.345 | J43: 87.88 | K43: 105.119
...

Sheet ALGN(CF)
A2: Align Technology Inc (ALGN US) - Standardized
A4: In Millions of USD except Per Share | C4: FY 2007 | D4: FY 2008 | E4: FY 2009 | F4: FY 2010 | G4: FY 2011 | H4: FY 2012 | I4: FY 2013 | J4: FY 2014 | K4: FY 2015 | S4: Last 12M
A5: 12 Months Ending | C5: 12/31/2007 | D5: 12/31/2008 | E5: 12/31/2009 | F5: 12/31/2010 | G5: 12/31/2011 | H5: 12/31/2012 | I5: 12/31/2013 | J5: 12/31/2014 | K5: 12/31/2015 | L5: 2016 | M5: 2017 | N5: 2018 | O5: 2019 | P5: 2020 | Q5: CAGR | R5: AVG | S5: 09/30/2016
A6: Cash from Operating Activities
A7: + Net Income | B7: CF_NET_INC | C7: 35.724 | D7: 79.987 | E7: -31.269 | F7: 74.253 | G7: 66.716 | H7: 58.691 | I7: 64.295 | J7: 145.832 | K7: 144.02 | S7: 190.938
A8: + Depreciation & Amortization | B8: CF_DEPR_AMORT | C8: 13.385 | D8: 12.791 | E8: 13.004 | F8: 14.186 | G8: 17.477 | H8: 17.811 | I8: 16.825 | J8: 17.856 | K8: 18.004 | L8: =L9*'ALGN(IS)'!L$6 -> 19.446178 | M8: =M9*'ALGN(IS)'!M$6 -> 22.363105 | N8: =N9*'ALGN(IS)'!N$6 -> 25.046677 | O8: =O9*'ALGN(IS)'!O$6 -> 27.551345 | P8: =P9*'ALGN(IS)'!P$6 -> 30.306479 | S8: 21.649
A9: % revenu | C9: =C8/'ALGN(IS)'!C$6 -> 0.04707525 | D9: =D8/'ALGN(IS)'!D$6 -> 0.04207898 | E9: =E8/'ALGN(IS)'!E$6 -> 0.04163505 | F9: =F8/'ALGN(IS)'!F$6 -> 0.0366444 | G9: =G8/'ALGN(IS)'!G$6 -> 0.036430074 | H9: =H8/'ALGN(IS)'!H$6 -> 0.031803029 | I9: =I8/'ALGN(IS)'!I$6 -> 0.02548447 | J9: =J8/'ALGN(IS)'!J$6 -> 0.023443747 | K9: =K8/'ALGN(IS)'!K$6 -> 0.021294262 | L9: 0.02 | M9: 0.02 | N9: 0.02 | O9: 0.02 | P9: 0.02 | Q9: =(K8/G8)^(1/5)-1 -> 0.0059593315 | R9: =AVERAGE(G9:K9) -> 0.027691116
A10: + Non-Cash Items | B10: NON_CASH_ITEMS_DETAILED | C10: 13.222 | D10: -44.721 | E10: 76.546 | F10: 30.497 | G10: 13.734 | H10: 60.659 | I10: 91.694 | J10: 54.017 | K10: 44.922 | S10: 32.755
A11: + Stock-Based Compensation | B11: CF_STOCK_BASED_COMPENSATION | C11: 12.211 | D11: 16.913 | E11: 15.725 | F11: 12.107 | G11: 7.774 | H11: 4.296 | I11: -0.665 | J11: 18.43 | K11: 42.547 | S11: 51.123
A12: + Deferred Income Taxes | B12: CF_DEF_INC_TAX | C12: 0 | D12: -64.608 | E12: -2.612 | F12: 17.307 | G12: 5.842 | H12: 17.783 | I12: 21.204 | J12: 25.481 | K12: -11.424 | S12: -32.917
A13: + Other Non-Cash Adj | B13: OTHER_NON_CASH_ADJ_LESS_DETAILED | C13: 1.011 | D13: 2.974 | E13: 63.433 | F13: 1.083 | G13: 0.118 | H13: 38.58 | I13: 71.155 | J13: 10.106 | K13: 13.799 | S13: 14.549
A14: + Chg in Non-Cash Work Cap | B14: CF_CHNG_NON_CASH_WORK_CAP | C14: -9.554 | D14: -8.311 | E14: 15.884 | F14: 10.593 | G14: 32.542 | H14: -3.383 | I14: 13.162 | J14: 9.194 | K14: 31.051 | L14: =L15*'ALGN(IS)'!L$6 -> 19.446178 | M14: =M15*'ALGN(IS)'!M$6 -> 22.363105 | N14: =N15*'ALGN(IS)'!N$6 -> 25.046677 | O14: =O15*'ALGN(IS)'!O$6 -> 27.551345 | P14: =P15*'ALGN(IS)'!P$6 -> 30.306479 | S14: 0.687
A15: % revenu | C15: =C14/'ALGN(IS)'!C$6 -> -0.033601564 | D15: =D14/'ALGN(IS)'!D$6 -> -0.027340974 | E15: =E14/'ALGN(IS)'!E$6 -> 0.050855977 | F15: =F14/'ALGN(IS)'!F$6 -> 0.027363184 | G15: =G14/'ALGN(IS)'!G$6 -> 0.067832435 | H15: =H14/'ALGN(IS)'!H$6 -> -0.0060406292 | I15: =I14/'ALGN(IS)'!I$6 -> 0.019936202 | J15: =J14/'ALGN(IS)'!J$6 -> 0.012071114 | K15: =K14/'ALGN(IS)'!K$6 -> 0.036725623 | L15: 0.02 | M15: 0.02 | N15: 0.02 | O15: 0.02 | P15: 0.02 | Q15: =(K14/G14)^(1/5)-1 -> -0.0093362537 | R15: =AVERAGE(G15:K15) -> 0.026104949
A16: + (Inc) Dec in Accts Receiv | B16: CF_ACCT_RCV_UNBILLED_REV | C16: -10.703 | D16: -7.951 | E16: -2.586 | F16: -12.184 | G16: -21.693 | H16: -9.138 | I16: -11.981 | J16: -27.229 | K16: -40.775 | S16: -106.774
A17: + (Inc) Dec in Inventories | B17: CF_CHANGE_IN_INVENTORIES | C17: 0.186 | D17: 0.943 | E17: -0.085 | F17: -0.508 | G17: -4.058 | H17: -5.718 | I17: 1.158 | J17: -1.999 | K17: -3.563 | S17: -7.4029999
A18: + Inc (Dec) in Accts Payable | B18: CF_CHANGE_IN_ACCOUNTS_PAYABLE | C18: 2.738 | D18: -2.651 | E18: -0.614 | F18: 2.612 | G18: 7.535 | H18: -0.006 | I18: -0.186 | J18: 2.887 | K18: 7.575 | S18: -0.967
A19: + Inc (Dec) in Other | B19: INC_DEC_IN_OT_OP_AST_LIAB_DETAIL | C19: -1.775 | D19: 1.348 | E19: 19.169 | F19: 20.673 | G19: 50.758 | H19: 11.479 | I19: 24.171 | J19: 35.535 | K19: 67.814 | S19: 115.831
A20: + Net Cash From Disc Ops | B20: CF_NET_CASH_DISCONT_OPS_OPER | C20: — | D20: — | E20: 0 | F20: 0 | G20: 0 | H20: 0 | I20: 0 | J20: 0 | K20: 0 | S20: 0
A21: Cash from Operating Activities | B21: CF_CASH_FROM_OPER | C21: 52.777 | D21: 39.746 | E21: 74.165 | F21: 129.529 | G21: 130.469 | H21: 133.778 | I21: 185.976 | J21: 226.899 | K21: 237.997 | S21: 246.029
A23: Cash from Investing Activities
A24: + Change in Fixed & Intang | B24: CHG_IN_FXD_&_INTANG_AST_DETAILED | C24: -7.429 | D24: -14.145 | E24: -7.192 | F24: -18.031 | G24: -30.309 | H24: -38.333 | I24: -19.412 | J24: -24.092 | K24: -53.451 | S24: -73.156
A25: + Disp in Fixed & Intang | B25: DISP_FXD_&_INTANGIBLES_DETAILED | C25: 0 | D25: 0.189 | E25: 0 | F25: 0 | G25: 0.095 | H25: 0 | I25: 0 | J25: 0 | K25: 0 | S25: 0
A26: + Disp of Fixed Prod Assets | B26: CF_DISPOSAL_OF_FIXED_PROD_ASSETS | C26: — | D26: — | E26: — | F26: — | G26: 0.095 | H26: — | I26: — | J26: — | K26: 0 | S26: 0
A27: + Disp of Intangible Assets | B27: CF_DISPOSAL_OF_INTANGIBLE_ASSETS | C27: — | D27: — | E27: 0 | F27: 0 | G27: 0 | H27: 0 | I27: 0 | J27: 0 | K27: 0 | S27: 0
A28: + Acq of Fixed & Intang | B28: ACQUIS_FXD_&_INTANG_DETAILED | C28: -7.429 | D28: -14.334 | E28: -7.192 | F28: -18.031 | G28: -30.404 | H28: -38.333 | I28: -19.412 | J28: -24.092 | K28: -53.451 | S28: -73.156
A29: + Acq of Fixed Prod Assets | B29: CF_PURCHASE_OF_FIXED_PROD_ASSETS | C29: — | D29: — | E29: -7.192 | F29: -18.031 | G29: -30.404 | H29: -38.333 | I29: -19.412 | J29: -24.092 | K29: -53.451 | L29: =L30*'ALGN(IS)'!L$6 -> -48.615445 | M29: =M30*'ALGN(IS)'!M$6 -> -55.907762 | N29: =N30*'ALGN(IS)'!N$6 -> -62.616693 | O29: =O30*'ALGN(IS)'!O$6 -> -68.878362 | P29: =P30*'ALGN(IS)'!P$6 -> -75.766199 | S29: -73.156
A30: % revenu | C30: =C29/'ALGN(IS)'!C$6 -> #VALUE! | D30: =D29/'ALGN(IS)'!D$6 -> #VALUE! | E30: =E29/'ALGN(IS)'!E$6 -> -0.023026705 | F30: =F29/'ALGN(IS)'!F$6 -> -0.046576567 | G30: =G29/'ALGN(IS)'!G$6 -> -0.063375863 | H30: =H29/'ALGN(IS)'!H$6 -> -0.068446774 | I30: =I29/'ALGN(IS)'!I$6 -> -0.029402944 | J30: =J29/'ALGN(IS)'!J$6 -> -0.031631202 | K30: =K29/'ALGN(IS)'!K$6 -> -0.063219261 | L30: -0.05 | M30: -0.05 | N30: -0.05 | O30: -0.05 | P30: -0.05 | Q30: =(K29/G29)^(1/5)-1 -> 0.11945083 | R30: =AVERAGE(G30:K30) -> -0.051215209
A31: + Acq of Intangible Assets | B31: CF_ACQUISITION_OF_INTANG_ASSETS | C31: — | D31: — | E31: 0 | F31: 0 | G31: 0 | H31: 0 | I31: 0 | J31: 0 | K31: 0 | S31: 0
A32: + Net Change in LT Investment | B32: NET_CHG_IN_LT_INVEST_DETAILED | C32: 0 | D32: 0 | E32: 0 | F32: 0 | G32: 0 | H32: 0 | I32: 0 | J32: 0 | K32: 0 | S32: 0
A33: + Dec in LT Investment | B33: CF_DECR_INVEST | C33: 0 | D33: 0 | E33: 0 | F33: 0 | G33: 0 | H33: 0 | I33: 0 | J33: 0 | K33: 0 | S33: 0
A34: + Inc in LT Investment | B34: CF_INCR_INVEST | C34: 0 | D34: 0 | E34: 0 | F34: 0 | G34: 0 | H34: 0 | I34: 0 | J34: 0 | K34: 0 | S34: 0
A35: + Net Cash From Acq & Div | B35: CF_NT_CSH_RCVD_PD_FOR_ACQUIS_DIV | C35: — | D35: — | E35: 0 | F35: 0 | G35: -187.588 | H35: 0 | I35: -7.652 | J35: 0 | K35: 0 | S35: 0
A36: + Cash from Divestitures | B36: CF_CASH_FOR_DIVESTITURES | C36: — | D36: — | E36: 0 | F36: 0 | G36: 0 | H36: 0 | I36: 0 | J36: 0 | K36: 0 | S36: 0
A37: + Cash for Acq of Subs | B37: CF_CASH_FOR_ACQUIS_SUBSIDIARIES | C37: — | D37: — | E37: 0 | F37: 0 | G37: -187.588 | H37: 0 | I37: -7.652 | J37: 0 | K37: 0 | S37: 0
A38: + Cash for JVs | B38: CF_CASH_FOR_JOINT_VENTURES_ASSOC | C38: — | D38: — | E38: 0 | F38: 0 | G38: 0 | H38: 0 | I38: 0 | J38: 0 | K38: 0 | S38: 0
A39: + Other Investing Activities | B39: OTHER_INVESTING_ACT_DETAILED | C39: -29.35 | D39: 13.09 | E39: 5.636 | F39: 2.111 | G39: 6.291 | H39: -39.967 | I39: -183.67 | J39: -177.535 | K39: -112.91 | S39: 142.279
A40: + Net Cash From Disc Ops | B40: CF_NET_CASH_DISCONTINUED_OPS_INV | C40: — | D40: — | E40: 0 | F40: 0 | G40: 0 | H40: 0 | I40: 0 | J40: 0 | K40: 0 | S40: 0
A41: Cash from Investing Activities | B41: CF_CASH_FROM_INV_ACT | C41: -36.779 | D41: -1.055 | E41: -1.556 | F41: -15.92 | G41: -211.606 | H41: -78.3 | I41: -210.734 | J41: -201.627 | K41: -166.361 | S41: 69.122998
A43: Cash from Financing Activities
A44: + Dividends Paid | B44: CF_DVD_PAID | C44: 0 | D44: 0 | E44: 0 | F44: 0 | G44: 0 | H44: 0 | I44: 0 | J44: 0 | K44: 0 | S44: 0
...

Sheet ALGN(BS)
A2: Align Technology Inc (ALGN US) - Standardized
A4: In Millions of USD except Per Share | C4: Q4 2013 | D4: Q1 2014 | E4: Q2 2014 | F4: Q3 2014 | G4: Q4 2014 | H4: Q1 2015 | I4: Q2 2015 | J4: Q3 2015 | K4: Q4 2015 | L4: Q1 2016 | M4: Q2 2016 | N4: Q3 2016
A5: 3 Months Ending | C5: 12/31/2013 | D5: 03/31/2014 | E5: 06/30/2014 | F5: 09/30/2014 | G5: 12/31/2014 | H5: 03/31/2015 | I5: 06/30/2015 | J5: 09/30/2015 | K5: 12/31/2015 | L5: 03/31/2016 | M5: 06/30/2016 | N5: 09/30/2016
A6: Total Assets
A7: + Cash, Cash Equivalents & STI | B7: C&CE_AND_STI_DETAILED | C7: 369.993 | D7: 366.443 | E7: 365.53 | F7: 425.496 | G7: 454.658 | H7: 444.801 | I7: 438.542 | J7: 484.755 | K7: 527.295 | L7: 548.078 | M7: 571.813 | N7: 612.966
A8: + Cash & Cash Equivalents | B8: BS_CASH_NEAR_CASH_ITEM | C8: 242.953 | D8: 182.766 | E8: 167.471 | F8: 180.676 | G8: 199.871 | H8: 189.978 | I8: 161.753 | J8: 174.04 | K8: 167.714 | L8: 154.418 | M8: 167.706 | N8: 419.948
A9: + ST Investments | B9: BS_MKT_SEC_OTHER_ST_INVEST | C9: 127.04 | D9: 183.677 | E9: 198.059 | F9: 244.82 | G9: 254.787 | H9: 254.823 | I9: 276.789 | J9: 310.715 | K9: 359.581 | L9: 393.66 | M9: 404.107 | N9: 193.018
A10: + Accounts & Notes Receiv | B10: BS_ACCT_NOTE_RCV | C10: 113.25 | D10: 126.183 | E10: 131.028 | F10: 130.047 | G10: 129.751 | H10: 138.159 | I10: 146.466 | J10: 148.395 | K10: 158.55 | L10: 178 | M10: 192.66 | N10: 244.992
A11: + Accounts Receivable, Net | B11: BS_ACCTS_REC_EXCL_NOTES_REC | C11: 113.25 | D11: 126.183 | E11: 131.028 | F11: 130.047 | G11: 129.751 | H11: 138.159 | I11: 146.466 | J11: 148.395 | K11: 158.55 | L11: 178 | M11: 192.66 | N11: 244.992
A12: + Notes Receivable, Net | B12: NOTES_RECEIVABLE | C12: 0 | D12: 0 | E12: 0 | F12: 0 | G12: 0 | H12: 0 | I12: 0 | J12: 0 | K12: 0 | L12: 0 | M12: 0 | N12: 0
A13: + Inventories | B13: BS_INVENTORIES | C13: 13.968 | D13: 15.84 | E13: 13.115 | F13: 15.983 | G13: 15.928 | H13: 14.572 | I13: 16.415 | J13: 18.939 | K13: 19.465 | L13: 22.618 | M13: 22.992 | N13: 26.341
A14: + Raw Materials | B14: INVTRY_RAW_MATERIALS | C14: 5.172 | D14: 5.962 | E14: 3.493 | F14: 6.24 | G14: 8.143 | H14: 5.99 | I14: 7.352 | J14: 9.69 | K14: 9.95 | L14: 9.676 | M14: 8.217 | N14: 12.018
A15: + Work In Process | B15: INVTRY_IN_PROGRESS | C15: 4.241 | D15: 3.592 | E15: 3.43 | F15: 3.734 | G15: 2.97 | H15: 4.487 | I15: 5.243 | J15: 6.659 | K15: 7.067 | L15: 9.939 | M15: 10.889 | N15: 1.488
A16: + Finished Goods | B16: INVTRY_FINISHED_GOODS | C16: 4.555 | D16: 6.286 | E16: 6.192 | F16: 6.009 | G16: 4.815 | H16: 4.095 | I16: 3.82 | J16: 2.59 | K16: 2.448 | L16: 3.003 | M16: 3.886 | N16: 12.835
A17: + Other Inventory | B17: BS_OTHER_INV | C17: 0 | D17: 0 | E17: 0 | F17: 0 | G17: 0 | H17: 0 | I17: 0 | J17: 0 | K17: 0 | L17: 0 | M17: 0 | N17: 0
A18: + Other ST Assets | B18: OTHER_CURRENT_ASSETS_DETAILED | C18: 47.465 | D18: 43.711 | E18: 44.839 | F18: 44.146 | G18: 56.823 | H18: 59.78 | I18: 56.483 | J18: 59.644 | K18: 26.7 | L18: 34.307 | M18: 37.942 | N18: 27.469
A19: + Derivative & Hedging Assets | B19: BS_DERIV_&_HEDGING_ASSETS_ST | C19: 0 | D19: — | E19: — | F19: — | G19: 0 | H19: — | I19: — | J19: — | K19: 0 | L19: — | M19: — | N19: —
A20: + Deferred Tax Assets | B20: BS_DEFERRED_TAX_ASSETS_ST | C20: — | D20: — | E20: — | F20: — | G20: 37.053 | H20: 29.911 | I20: 29.972 | J20: 30.09 | K20: 0 | L20: — | M20: — | N20: —
A21: + Misc ST Assets | B21: BS_OTHER_CUR_ASSET_LESS_PREPAY | C21: 47.465 | D21: 43.711 | E21: 44.839 | F21: 44.146 | G21: 19.77 | H21: 29.869 | I21: 26.511 | J21: 29.554 | K21: 26.7 | L21: 34.307 | M21: 37.942 | N21: 27.469
A22: Total Current Assets | B22: BS_CUR_ASSET_REPORT | C22: 544.676 | D22: 552.177 | E22: 554.512 | F22: 615.672 | G22: 657.16 | H22: 657.312 | I22: 657.906 | J22: 711.733 | K22: 732.01 | L22: 783.003 | M22: 825.407 | N22: 911.768
A23: + Property, Plant & Equip, Net | B23: BS_NET_FIX_ASSET | C23: 75.743 | D23: 79.093 | E23: 81.312 | F23: 86.447 | G23: 90.125 | H23: 99.764 | I23: 108.029 | J23: 120.738 | K23: 136.473 | L23: 148.029 | M23: 161.685 | N23: 172.658
A24: + Property, Plant & Equip | B24: BS_GROSS_FIX_ASSET | C24: 181.249 | D24: — | E24: — | F24: — | G24: 197.927 | H24: — | I24: — | J24: — | K24: 254.51 | L24: — | M24: — | N24: —
A25: - Accumulated Depreciation | B25: BS_ACCUM_DEPR | C25: 105.506 | D25: — | E25: — | F25: — | G25: 107.802 | H25: — | I25: — | J25: — | K25: 118.037 | L25: — | M25: — | N25: —
A26: + LT Investments & Receivables | B26: BS_LT_INVEST | C26: 101.978 | D26: 138.929 | E26: 137.148 | F26: 136.017 | G26: 147.892 | H26: 168.171 | I26: 158.161 | J26: 145.246 | K26: 151.37 | L26: 132.69 | M26: 113.158 | N26: 62.82
A27: + LT Marketable Securities | B27: BS_LT_MARKETABLE_SECURITIES | C27: 101.978 | D27: 138.929 | E27: 137.148 | F27: 136.017 | G27: 147.892 | H27: 168.171 | I27: 158.161 | J27: 145.246 | K27: 151.37 | L27: 132.69 | M27: 113.158 | N27: 62.82
A28: + Other LT Assets | B28: BS_OTHER_ASSETS_DEF_CHRG_OTHER | C28: 109.75 | D28: 115.442 | E28: 112.461 | F28: 48.564 | G28: 92.82 | H28: 103.158 | I28: 104.485 | J28: 101.845 | K28: 138.78 | L28: 143.838 | M28: 151.023 | N28: 211.647
A29: + Total Intangible Assets | B29: BS_DISCLOSED_INTANGIBLES | C29: 85.362 | D29: 84.388 | E29: 83.795 | F29: 82.926 | G29: 82.056 | H29: 81.274 | I29: 80.59 | J29: 79.715 | K29: 79.162 | L29: 78.606 | M29: 83.749 | N29: 82.987
A30: + Goodwill | B30: BS_GOODWILL | C30: 61.623 | D30: 61.751 | E30: 61.807 | F30: 61.589 | G30: 61.369 | H30: 61.237 | I30: 61.203 | J30: 60.978 | K30: 61.074 | L30: 61.168 | M30: 61.119 | N30: 61.195
A31: + Other Intangible Assets | B31: OTHER_INTANGIBLE_ASSETS_DETAILED | C31: 23.739 | D31: 22.637 | E31: 21.988 | F31: 21.337 | G31: 20.687 | H31: 20.037 | I31: 19.387 | J31: 18.737 | K31: 18.088 | L31: 17.438 | M31: 22.63 | N31: 21.792
A32: + Deferred Tax Assets | B32: BS_DEFERRED_TAX_ASSETS_LT | C32: 15.766 | D32: 22.739 | E32: 20.456 | F32: 19.714 | G32: 3.099 | H32: 14.63 | I32: 16.014 | J32: 14.542 | K32: 51.416 | L32: 57.527 | M32: 60.051 | N32: 68.918
A33: + Derivative & Hedging Assets | B33: BS_DERIV_&_HEDGING_ASSETS_LT | C33: 0 | D33: — | E33: — | F33: — | G33: 0 | H33: — | I33: — | J33: — | K33: 0 | L33: — | M33: — | N33: —
A34: + Investments in Affiliates | B34: BS_INVEST_IN_ASSOC_CO | C34: — | D34: — | E34: — | F34: — | G34: — | H34: — | I34: — | J34: — | K34: — | L34: — | M34: — | N34: 46.268
A35: + Misc LT Assets | B35: OTHER_NONCURRENT_ASSETS_DETAILED | C35: 8.622 | D35: 8.315 | E35: 8.21 | F35: 7.513 | G35: 7.665 | H35: 7.254 | I35: 7.881 | J35: 7.588 | K35: 8.202 | L35: 7.705 | M35: 7.223 | N35: 13.474
A36: Total Noncurrent Assets | B36: BS_TOT_NON_CUR_ASSET | C36: 287.471 | D36: 333.464 | E36: 330.921 | F36: 271.028 | G36: 330.837 | H36: 371.093 | I36: 370.675 | J36: 367.829 | K36: 426.623 | L36: 424.557 | M36: 425.866 | N36: 447.125
A37: Total Assets | B37: BS_TOT_ASSET | C37: 832.147 | D37: 885.641 | E37: 885.433 | F37: 948.289 | G37: 987.997 | H37: 1028.405 | I37: 1028.581 | J37: 1079.562 | K37: 1158.633 | L37: 1207.56 | M37: 1251.273 | N37: 1358.893
A39: Liabilities & Shareholders' Equity
A40: + Payables & Accruals | B40: ACCT_PAYABLE_&_ACCRUALS_DETAILED | C40: 98.063 | D40: 89.855 | E40: 101.988 | F40: 111.117 | G40: 111.127 | H40: 106.707 | I40: 121.505 | J40: 128.513 | K40: 142.119 | L40: 128.981 | M40: 138.432 | N40: 165.642
A41: + Accounts Payable | B41: BS_ACCT_PAYABLE | C41: 17.718 | D41: 18.506 | E41: 20.939 | F41: 24.517 | G41: 23.247 | H41: 24.996 | I41: 29.513 | J41: 32.599 | K41: 34.354 | L41: 36.258 | M41: 30.927 | N41: 33.104
A42: + Accrued Taxes | B42: BS_TAXES_PAYABLE | C42: 0 | D42: — | E42: 8.695 | F42: — | G42: 0 | H42: — | I42: 1.939 | J42: 2.4 | K42: 2.646 | L42: 1.793 | M42: 3.385 | N42: 5.043
A43: + Interest & Dividends Payable | B43: BS_INTEREST_&_DIVIDENDS_PAYABLE | C43: 0 | D43: — | E43: — | F43: — | G43: 0 | H43: — | I43: — | J43: — | K43: 0 | L43: — | M43: — | N43: —
...

Sheet DCF
A1: (1)_FCF Projections
A3: (in millions) | C3: 2004 | D3: 2005 | E3: 2006 | F3: 2007 | G3: 2008 | H3: 2009 | I3: 2010 | J3: 2011 | K3: 2012 | L3: 2013 | M3: 2014 | N3: 2015 | O3: 2016 | P3: 2017 | Q3: 2018 | R3: 2019 | S3: 2020 | T3: (NOTES:)
A4: Earnings Before Interest and Taxes | F4: ='ALGN(IS)'!C25 -> 32.059 | G4: ='ALGN(IS)'!D25 -> 21.745 | H4: ='ALGN(IS)'!E25 -> 36.98 | I4: ='ALGN(IS)'!F25 -> 98.617 | J4: ='ALGN(IS)'!G25 -> 101.472 | K4: ='ALGN(IS)'!H25 -> 124.234 | L4: ='ALGN(IS)'!I25 -> 161.225 | M4: ='ALGN(IS)'!J25 -> 193.576 | ... S4: ='ALGN(IS)'!P25 -> 359.88944 | V4: =(S4/O4)^(1/COUNT(O4:S4))-1 -> 0.092798894
A5: Effective Tax Rate | F5: 0.35 | G5: 0.23 | H5: 0.23 | I5: 0.23 | J5: 0.23 | K5: 0.23 | L5: 0.23 | M5: 0.23 | N5: 0.23 | O5: 0.23 | P5: 0.23 | Q5: 0.23 | R5: 0.23 | S5: 0.23
A6: x (1-Tax Rate) | C6: =C4*(1-C5) -> 0 | D6: =D4*(1-D5) -> 0 | E6: =E4*(1-E5) -> 0 | F6: =F4*(1-F5) -> 20.83835 | G6: =G4*(1-G5) -> 16.74365 | H6: =H4*(1-H5) -> 28.4746 | I6: =I4*(1-I5) -> 75.93509 | J6: =J4*(1-J5) -> 78.13344 | ... S6: =S4*(1-S5) -> 277.11487
A7: + Depreciation and Amortization | F7: ='ALGN(CF)'!C8 -> 13.385 | G7: ='ALGN(CF)'!D8 -> 12.791 | H7: ='ALGN(CF)'!E8 -> 13.004 | I7: ='ALGN(CF)'!F8 -> 14.186 | J7: ='ALGN(CF)'!G8 -> 17.477 | K7: ='ALGN(CF)'!H8 -> 17.811 | L7: ='ALGN(CF)'!I8 -> 16.825 | M7: ='ALGN(CF)'!J8 -> 17.856 | ... S7: ='ALGN(CF)'!P8 -> 30.306479
A8: - Capital Expenditures (FIX)*-1 | F8: 0 | G8: 0 | H8: ='ALGN(CF)'!E29*-1 -> 7.192 | I8: ='ALGN(CF)'!F29*-1 -> 18.031 | J8: ='ALGN(CF)'!G29*-1 -> 30.404 | K8: ='ALGN(CF)'!H29*-1 -> 38.333 | L8: ='ALGN(CF)'!I29*-1 -> 19.412 | M8: ='ALGN(CF)'!J29*-1 -> 24.092 | N8: ='ALGN(CF)'!K29*-1 -> 53.451 | O8: ='ALGN(CF)'!L29*-1 -> 48.615445 | ... S8: ='ALGN(CF)'!P29*-1 -> 75.766199
A9: - Change in Net Working Capital | F9: ='ALGN(CF)'!C14 -> -9.554 | G9: ='ALGN(CF)'!D14 -> -8.311 | H9: ='ALGN(CF)'!E14 -> 15.884 | I9: ='ALGN(CF)'!F14 -> 10.593 | J9: ='ALGN(CF)'!G14 -> 32.542 | K9: ='ALGN(CF)'!H14 -> -3.383 | L9: ='ALGN(CF)'!I14 -> 13.162 | M9: ='ALGN(CF)'!J14 -> 9.194 | ... S9: ='ALGN(CF)'!P14 -> 30.306479 | U9: Avg(5yr) | V9: CAGR(5yr)
A10: = Free Cash Flow | C10: =C6+C7-C8-C9 -> 0 | D10: =D6+D7-D8-D9 -> 0 | E10: =E6+E7-E8-E9 -> 0 | F10: =F6+F7-F8-F9 -> 43.77735 | G10: =G6+G7-G8-G9 -> 37.84565 | H10: =H6+H7-H8-H9 -> 18.4026 | I10: =I6+I7-I8-I9 -> 61.49709 | J10: =J6+J7-J8-J9 -> 32.66444 | ... S10: =S6+S7-S8-S9 -> 201.34867 | U10: =AVERAGE(O11:S11) -> 0.22211492 | V10: =(S10/O10)^(1/COUNT(O10:S10))-1 -> 0.092798894
A11: Growth yoy | D11: =(D10-C10)/C10 -> #DIV/0! | E11: =(E10-D10)/D10 -> #DIV/0! | F11: =(F10-E10)/E10 -> #DIV/0! | G11: =(G10-F10)/F10 -> -0.13549701 | H11: =(H10-G10)/G10 -> -0.51374597 | I11: =(I10-H10)/H10 -> 2.3417609 | J11: =(J10-I10)/I10 -> -0.46884576 | K11: =(K10-J10)/J10 -> 1.4038734 | ... S11: =(S10-R10)/R10 -> 0.1
A12: 3 year moving average | F12: =AVERAGE(D11:F11) -> #DIV/0! | G12: =AVERAGE(E11:G11) -> #DIV/0! | H12: =AVERAGE(F11:H11) -> #DIV/0! | I12: =AVERAGE(G11:I11) -> 0.56417266 | J12: =AVERAGE(H11:J11) -> 0.45305641 | K12: =AVERAGE(I11:K11) -> 1.0922629 | L12: =AVERAGE(J11:L11) -> 0.43849123 | M12: =AVERAGE(K11:M11) -> 0.67235805 | ... S12: =AVERAGE(Q11:S11) -> 0.10666667
A13: 5 year moving average | H13: =AVERAGE(D11:H11) -> #DIV/0! | I13: =AVERAGE(E11:I11) -> #DIV/0! | J13: =AVERAGE(F11:J11) -> #DIV/0! | K13: =AVERAGE(G11:K11) -> 0.52550913 | L13: =AVERAGE(H11:L11) -> 0.62869774 | M13: =AVERAGE(I11:M11) -> 0.77799787 | N13: =AVERAGE(J11:N11) -> 0.22751442 | O13: =AVERAGE(K11:O11) -> 0.44939849 | ... S13: =AVERAGE(O11:S11) -> 0.22211492
AC14: max | AD14: =MAX(Y24:AC38) -> 113.40162
AC15: min | AD15: =MIN(Y24:AC38) -> 70.785563
A16: (2)_WACC | Z16: EBITDA_5 vs. WACC | AC16: avg | AD16: =AVERAGE(Y24:AC38) -> 90.284223
Y17: =(Y18-$AA18)/$AA18 -> -0.19 | Z17: =(Z18-$AA18)/$AA18 -> -0.1 | AA17: =(AA18-$AA18)/$AA18 -> 0 | AB17: =(AB18-$AA18)/$AA18 -> 0.1 | AC17: =(AC18-$AA18)/$AA18 -> 0.21
A18: RF (10yr UST) | B18: 0.016 | S18: =B68 -> 92.452066 | T18: =U18*(1-10%) -> 1.866295e+08 | U18: =V18*(1-10%) -> 2.0736611e+08 | V18: =W18*(1-10%) -> 2.3040679e+08 | W18: =X18*(1-10%) -> 2.5600755e+08 | X18: =Y18*(1-10%) -> 2.8445283e+08 | Y18: =Z18*(1-10%) -> 3.160587e+08 | Z18: =AA18*(1-10%) -> 3.5117633e+08 | AA18: 3.9019592e+08 | AB18: =AA18*(1+10%) -> 4.2921552e+08 | AC18: =AB18*(1+10%) -> 4.7213707e+08 | AD18: =AC18*(1+10%) -> 5.1935077e+08 | AE18: =AD18*(1+10%) -> 5.7128585e+08 | AF18: =AE18*(1+10%) -> 6.2841444e+08
A19: RM | B19: 0.09 | R19: =(S19-S$30)/S$30 -> -0.25137112 | S19: =S20-0.25% -> 0.0819 | T19: 56.76555 | U19: 61.319709 | V19: 66.379885 | W19: 72.002303 | X19: 78.249434 | Y19: 85.190691 | Z19: 92.903199 | AA19: 101.47265 | AB19: 110.0421 | AC19: 119.4685 | AD19: 129.83754 | AE19: 141.24348 | AF19: 153.79002
A20: Beta2yr | B20: 1.1 | R20: =(S20-S$30)/S$30 -> -0.2285192 | S20: =S21-0.25% -> 0.0844 | T20: 56.23825 | U20: 60.740154 | V20: 65.742269 | W20: 71.300175 | X20: 77.475626 | Y20: 84.337239 | Z20: 91.961252 | AA20: 100.43238 | AB20: 108.9035 | AC20: 118.22174 | AD20: 128.47181 | AE20: 139.74688 | AF20: 152.14945
A21: Beta5yr | B21: 1.3 | R21: =(S21-S$30)/S$30 -> -0.20566728 | S21: =S22-0.25% -> 0.0869 | T21: 55.718025 | U21: 60.168392 | V21: 65.113244 | W21: 70.607524 | X21: 76.71228 | Y21: 83.495342 | Z21: 91.032077 | AA21: 99.406228 | AB21: 107.78038 | AC21: 116.99194 | AD21: 127.12467 | AE21: 138.27066 | AF21: 150.53125
A22: BetaAVG | B22: =SUM(B20:B21)/2 -> 1.2 | R22: =(S22-S$30)/S$30 -> -0.18281536 | S22: =S23-0.25% -> 0.0894 | T22: 55.204764 | U22: 59.6043 | V22: 64.492674 | W22: 69.9242 | X22: 75.95923 | Y22: 82.664818 | Z22: 90.115471 | AA22: 98.393975 | AB22: 106.67248 | AC22: 115.77883 | AD22: 125.79582 | AE22: 136.81451 | AF22: 148.93507
A23: CAPM (ke) | B23: =B18+B22*(B19-B18) -> 0.1048 | G23: Valuations: | R23: =(S23-S$30)/S$30 -> -0.15996344 | S23: =S24-0.25% -> 0.0919 | T23: 54.698357 | U23: 59.047758 | V23: 63.880425 | W23: 69.250056 | X23: 75.216312 | Y23: 81.845486 | Z23: 89.211234 | AA23: 97.395399 | AB23: 105.57956 | AC23: 114.58215 | AD23: 124.48499 | AE23: 135.37811 | AF23: 147.36054
A24: kd_pre | B24: 0 | G24: DCF _Perpetutiy | R24: =(S24-S$30)/S$30 -> -0.13711152 | S24: =S25-0.25% -> 0.0944 | T24: 54.198696 | U24: 58.498645 | V24: 63.276366 | W24: 68.584946 | X24: 74.483367 | Y24: 81.037169 | Z24: 88.319171 | AA24: 96.410285 | AB24: 104.5014 | AC24: 113.40162 | AD24: 123.19187 | AE24: 133.96114 | AF24: 145.80734 | AG24: =AVERAGE(Y24:AC24) -> 96.733929
A25: kd_post | B25: =B24*(1-N5) -> 0 | G25: Sensitivity_Analysis .P | R25: =(S25-S$30)/S$30 -> -0.1142596 | S25: =S26-0.25% -> 0.0969 | T25: 53.705675 | U25: 57.956846 | V25: 62.680369 | W25: 67.928728 | X25: 73.760239 | Y25: 80.239695 | Z25: 87.43909 | AA25: 95.438419 | AB25: 103.43775 | AC25: 112.23701 | AD25: 121.9162 | AE25: 132.5633 | AF25: 144.27512
A26: Shares Outstanding | B26: ='ALGN(BS)'!N80*1000000 -> 79867000 | R26: =(S26-S$30)/S$30 -> -0.091407678 | S26: =S27-0.25% -> 0.0994 | T26: 53.21919 | U26: 57.422245 | V26: 62.092307 | W26: 67.281264 | X26: 73.046772 | Y26: 79.452892 | Z26: 86.570802 | AA26: 94.479592 | AB26: 102.38838 | AC26: 111.08805 | AD26: 120.65769 | AE26: 131.18429 | AF26: 142.76355
A27: Current Price: | B27: 90.61 | G27: DCF _Growth | R27: =(S27-S$30)/S$30 -> -0.068555759 | S27: =S28-0.25% -> 0.1019 | T27: 52.73914 | U27: 56.894731 | V27: 61.512055 | W27: 66.642415 | X27: 72.342815 | Y27: 78.676592 | Z27: 85.714123 | AA27: 93.533601 | AB27: 101.35308 | AC27: 109.95451 | AD27: 119.41608 | AE27: 129.8238 | AF27: 141.2723
A28: ST Debt | B28: ='ALGN(BS)'!N45 -> 0 | G28: Sensitivity_Analysis .G | R28: =(S28-S$30)/S$30 -> -0.045703839 | S28: =S29-0.25% -> 0.1044 | T28: 52.265423 | U28: 56.374193 | V28: 60.939492 | W28: 66.012047 | X28: 71.648219 | Y28: 77.910633 | Z28: 84.86887 | AA28: 92.600244 | AB28: 100.33162 | AC28: 108.83613 | AD28: 118.19109 | AE28: 128.48155 | AF28: 139.80106
A29: LT Debt | B29: ='ALGN(BS)'!N53 -> 0 | R29: =(S29-S$30)/S$30 -> -0.02285192 | S29: =S30-0.25% -> 0.1069 | T29: 51.797943 | U29: 55.860522 | V29: 60.374498 | W29: 65.390028 | X29: 70.962839 | Y29: 77.154851 | Z29: 84.034864 | AA29: 91.679323 | AB29: 99.323782 | AC29: 107.73269 | AD29: 116.98248 | AE29: 127.15726 | AF29: 138.34951
A30: Total Debt | B30: 0 | C30: =B30/(B30+B31) -> 0 | G30: Dividend_Model | R30: =(S30-S$30)/S$30 -> 0 | S30: 0.1094 | T30: 51.336601 | U30: 55.353611 | V30: 59.816956 | W30: 64.776228 | X30: 70.28653 | Y30: 76.409088 | Z30: 83.211931 | AA30: 90.770644 | AB30: 98.329358 | AC30: 106.64394 | AD30: 115.78999 | AE30: 125.85063 | AF30: 136.91735
A31: Equity (Mkt Cap) | B31: =B26*B27 -> 7236748870 | C31: =1-C30 -> 1 | G31: Sensitivity_Analysis .D | R31: =(S31-S$30)/S$30 -> 0.02285192 | S31: =S30+0.25% -> 0.1119 | T31: 50.881303 | U31: 54.853356 | V31: 59.266749 | W31: 64.170519 | X31: 69.619153 | Y31: 75.67319 | Z31: 82.399897 | AA31: 89.874017 | AB31: 97.348137 | AC31: 105.56967 | AD31: 114.61335 | AE31: 124.56141 | AF31: 135.50427
R32: =(S32-S$30)/S$30 -> 0.045703839 | S32: =S31+0.25% -> 0.1144 | T32: 50.431955 | U32: 54.359655 | V32: 58.723765 | W32: 63.572777 | X32: 68.960567 | Y32: 74.947002 | Z32: 81.598595 | AA32: 88.989254 | AB32: 96.379914 | AC32: 104.50964 | AD32: 113.45234 | AE32: 123.2893 | AF32: 134.10997
A33: WACC | B33: =(B23*C31)+(B25*C30) -> 0.1048 | G33: Comparables_model | R33: =(S33-S$30)/S$30 -> 0.068555759 | S33: =S32+0.25% -> 0.1169 | T33: 49.988467 | U33: 53.872405 | V33: 58.187892 | W33: 62.982877 | X33: 68.310639 | Y33: 74.230374 | Z33: 80.807857 | AA33: 88.116172 | AB33: 95.424487 | AC33: 103.46363 | AD33: 112.30669 | AE33: 122.03406 | AF33: 132.73417
G34: SimSale_model | R34: =(S34-S$30)/S$30 -> 0.091407678 | S34: =S33+0.25% -> 0.1194 | T34: 49.550747 | U34: 53.391508 | V34: 57.65902 | W34: 62.4007 | X34: 67.669233 | Y34: 73.523159 | Z34: 80.027521 | AA34: 87.254589 | AB34: 94.481658 | AC34: 102.43143 | AD34: 111.17619 | AE34: 120.79542 | AF34: 131.37657
G35: Comp_EBITDA_model | R35: =(S35-S$30)/S$30 -> 0.1142596 | S35: =S34+0.25% -> 0.1219 | T35: 49.118708 | U35: 52.916866 | V35: 57.137042 | W35: 61.826126 | X35: 67.036219 | Y35: 72.825211 | Z35: 79.257425 | AA35: 86.404329 | AB35: 93.551234 | AC35: 101.41283 | AD35: 110.06058 | AE35: 119.57311 | AF35: 130.03689
A36: (3)_FCF_Perp/DCF/ValuePerShare | R36: =(S36-S$30)/S$30 -> 0.13711152 | S36: =S35+0.25% -> 0.1244 | T36: 48.692263 | U36: 52.448384 | V36: 56.621852 | W36: 61.259038 | X36: 66.411467 | Y36: 72.136389 | Z36: 78.497413 | AA36: 85.565217 | AB36: 92.633022 | AC36: 100.40761 | AD36: 108.95965 | AE36: 118.3669 | AF36: 128.71487
G37: Average_Value | R37: =(S37-S$30)/S$30 -> 0.15996344 | S37: =S36+0.25% -> 0.1269 | T37: 48.271326 | U37: 51.985967 | V37: 56.113346 | W37: 60.699323 | X37: 65.794852 | Y37: 71.456552 | Z37: 77.747329 | AA37: 84.737082 | AB37: 91.726835 | AC37: 99.415563 | AD37: 107.87316 | AE37: 117.17652 | AF37: 127.41022
A38: Perpetuity: (FCF(f)*(1+g))/(WACC-g) --> 0.5 to 4 | R38: =(S38-S$30)/S$30 -> 0.18281536 | S38: =S37+0.25% -> 0.1294 | T38: 47.855813 | U38: 51.529523 | V38: 55.611422 | W38: 60.146867 | X38: 65.186249 | Y38: 70.785563 | Z38: 77.007023 | AA38: 83.919756 | AB38: 90.832489 | AC38: 98.436495 | AD38: 106.8009 | AE38: 116.00175 | AF38: 126.12268
A39: Growth Rate Calc | B39: =V10 -> 0.092798894 | R39: =(S39-S$30)/S$30 -> 0.20566728 | S39: =S38+0.25% -> 0.1319 | T39: 47.445642 | U39: 51.07896 | V39: 55.115981 | W39: 59.601559 | X39: 64.585535 | Y39: 70.123286 | Z39: 76.276343 | AA39: 83.113072 | AB39: 89.949802 | AC39: 97.470205 | AD39: 105.74265 | AE39: 114.84233 | AF39: 124.85199
A40: Growth Rate Adj | B40: 0.02 | R40: =(S40-S$30)/S$30 -> 0.2285192 | S40: =S39+0.25% -> 0.1344 | T40: 47.040732 | U40: 50.634191 | V40: 54.626923 | W40: 59.063292 | X40: 63.992591 | Y40: 69.469589 | Z40: 75.555143 | AA40: 82.31687 | AB40: 89.078597 | AC40: 96.516496 | AD40: 104.69819 | AE40: 113.69804 | AF40: 123.59789
A41: Terminal Value | B41: =((S10*1000000)*(1+B40))/(B33-B40) -> 2.4218826e+09 | R41: =(S41-S$30)/S$30 -> 0.25137112 | S41: =S40+0.25% -> 0.1369 | T41: 46.641004 | U41: 50.195127 | V41: 54.144152 | W41: 58.531958 | X41: 63.407298 | Y41: 68.824342 | Z41: 74.84328 | AA41: 81.530989 | AB41: 88.218698 | AC41: 95.575178 | AD41: 103.66731 | AE41: 112.56865 | AF41: 122.36012
...

Sheet Credit
A1: CA | F1: ='ALGN(BS_Annual)'!C22 -> 184.517 | G1: ='ALGN(BS_Annual)'!D22 -> 177.907 | H1: ='ALGN(BS_Annual)'!E22 -> 261.299 | I1: ='ALGN(BS_Annual)'!F22 -> 388.611 | J1: ='ALGN(BS_Annual)'!G22 -> 384.816 | K1: ='ALGN(BS_Annual)'!H22 -> 485.793 | L1: ='ALGN(BS_Annual)'!I22 -> 544.676 | M1: ='ALGN(BS_Annual)'!J22 -> 657.16 | N1: ='ALGN(BS_Annual)'!K22 -> 732.01
A2: TA | F2: ='ALGN(BS_Annual)'!C36 -> 222.761 | G2: ='ALGN(BS_Annual)'!D36 -> 279.341 | H2: ='ALGN(BS_Annual)'!E36 -> 355.24 | I2: ='ALGN(BS_Annual)'!F36 -> 476.943 | J2: ='ALGN(BS_Annual)'!G36 -> 649.264 | K2: ='ALGN(BS_Annual)'!H36 -> 756.312 | L2: ='ALGN(BS_Annual)'!I36 -> 832.147 | M2: ='ALGN(BS_Annual)'!J36 -> 987.997 | N2: ='ALGN(BS_Annual)'!K36 -> 1158.633
A3: CL | F3: ='ALGN(BS_Annual)'!C51 -> 61.459 | G3: ='ALGN(BS_Annual)'!D51 -> 60.572 | H3: ='ALGN(BS_Annual)'!E51 -> 81.243 | I3: ='ALGN(BS_Annual)'!F51 -> 92.974 | J3: ='ALGN(BS_Annual)'!G51 -> 148.117 | K3: ='ALGN(BS_Annual)'!H51 -> 155.771 | L3: ='ALGN(BS_Annual)'!I51 -> 175.338 | M3: ='ALGN(BS_Annual)'!J51 -> 201.811 | N3: ='ALGN(BS_Annual)'!K51 -> 271.672
A4: TL | F4: ='ALGN(BS_Annual)'!C64 -> 61.607 | G4: ='ALGN(BS_Annual)'!D64 -> 60.801 | H4: ='ALGN(BS_Annual)'!E64 -> 82.204 | I4: ='ALGN(BS_Annual)'!F64 -> 99.196 | J4: ='ALGN(BS_Annual)'!G64 -> 158.483 | K4: ='ALGN(BS_Annual)'!H64 -> 174.995 | L4: ='ALGN(BS_Annual)'!I64 -> 198.177 | M4: ='ALGN(BS_Annual)'!J64 -> 235.226 | N4: ='ALGN(BS_Annual)'!K64 -> 310.707
A5: SO | F5: ='ALGN(BS_Annual)'!C79 -> 68.642 | G5: ='ALGN(BS_Annual)'!D79 -> 65.633 | H5: ='ALGN(BS_Annual)'!E79 -> 74.568 | I5: ='ALGN(BS_Annual)'!F79 -> 76.39 | J5: ='ALGN(BS_Annual)'!G79 -> 78.776 | K5: ='ALGN(BS_Annual)'!H79 -> 80.611 | L5: ='ALGN(BS_Annual)'!I79 -> 80.583 | M5: ='ALGN(BS_Annual)'!J79 -> 80.205 | N5: ='ALGN(BS_Annual)'!K79 -> 79.5
A6: Current Market Cap | F6: 1144.9486 | G6: 574.28875 | H6: 1328.8018 | I6: 1492.6606 | J6: 1868.9606 | K6: 2236.9552 | L6: 4604.5126 | M6: 4484.2616 | N6: 5235.075
A7: Sales (Rev) | F7: ='ALGN(IS)'!C6 -> 284.332 | G7: ='ALGN(IS)'!D6 -> 303.976 | H7: ='ALGN(IS)'!E6 -> 312.333 | I7: ='ALGN(IS)'!F6 -> 387.126 | J7: ='ALGN(IS)'!G6 -> 479.741 | K7: ='ALGN(IS)'!H6 -> 560.041 | L7: ='ALGN(IS)'!I6 -> 660.206 | M7: ='ALGN(IS)'!J6 -> 761.653 | N7: ='ALGN(IS)'!K6 -> 845.486
A8: RE | F8: ='ALGN(BS_Annual)'!C70 -> -289.65 | G8: ='ALGN(BS_Annual)'!D70 -> -221.23 | H8: ='ALGN(BS_Annual)'!E70 -> -252.499 | I8: ='ALGN(BS_Annual)'!F70 -> -178.246 | J8: ='ALGN(BS_Annual)'!G70 -> -116.513 | K8: ='ALGN(BS_Annual)'!H70 -> -89.626 | L8: ='ALGN(BS_Annual)'!I70 -> -95.91 | M8: ='ALGN(BS_Annual)'!J70 -> -30.507 | N8: ='ALGN(BS_Annual)'!K70 -> 27.391
A9: EBIT | F9: ='ALGN(IS)'!C25 -> 32.059 | G9: ='ALGN(IS)'!D25 -> 21.745 | H9: ='ALGN(IS)'!E25 -> 36.98 | I9: ='ALGN(IS)'!F25 -> 98.617 | J9: ='ALGN(IS)'!G25 -> 101.472 | K9: ='ALGN(IS)'!H25 -> 124.234 | L9: ='ALGN(IS)'!I25 -> 161.225 | M9: ='ALGN(IS)'!J25 -> 193.576 | N9: ='ALGN(IS)'!K25 -> 188.634
A10: D/A | F10: ='ALGN(CF)'!C8 -> 13.385 | G10: ='ALGN(CF)'!D8 -> 12.791 | H10: ='ALGN(CF)'!E8 -> 13.004 | I10: ='ALGN(CF)'!F8 -> 14.186 | J10: ='ALGN(CF)'!G8 -> 17.477 | K10: ='ALGN(CF)'!H8 -> 17.811 | L10: ='ALGN(CF)'!I8 -> 16.825 | M10: ='ALGN(CF)'!J8 -> 17.856 | N10: ='ALGN(CF)'!K8 -> 18.004
A11: EBITDA | F11: ='ALGN(IS)'!C12 -> 209.297 | G11: ='ALGN(IS)'!D12 -> 225.126 | H11: ='ALGN(IS)'!E12 -> 233.492 | I11: ='ALGN(IS)'!F12 -> 303.417 | J11: ='ALGN(IS)'!G12 -> 362.435 | K11: ='ALGN(IS)'!H12 -> 417.123 | L11: ='ALGN(IS)'!I12 -> 498.106 | M11: ='ALGN(IS)'!J12 -> 578.443 | N11: ='ALGN(IS)'!K12 -> 640.11
A12: NI | F12: ='ALGN(IS)'!C55 -> 35.724 | G12: ='ALGN(IS)'!D55 -> 79.987 | H12: ='ALGN(IS)'!E55 -> -31.269 | I12: ='ALGN(IS)'!F55 -> 74.253 | J12: ='ALGN(IS)'!G55 -> 66.716 | K12: ='ALGN(IS)'!H55 -> 58.691 | L12: ='ALGN(IS)'!I55 -> 64.295 | M12: ='ALGN(IS)'!J55 -> 145.832 | N12: ='ALGN(IS)'!K55 -> 144.02
A13: CFO | F13: ='ALGN(CF)'!C21 -> 52.777 | G13: ='ALGN(CF)'!D21 -> 39.746 | H13: ='ALGN(CF)'!E21 -> 74.165 | I13: ='ALGN(CF)'!F21 -> 129.529 | J13: ='ALGN(CF)'!G21 -> 130.469 | K13: ='ALGN(CF)'!H21 -> 133.778 | L13: ='ALGN(CF)'!I21 -> 185.976 | M13: ='ALGN(CF)'!J21 -> 226.899 | N13: ='ALGN(CF)'!K21 -> 237.997
A14: WC | F14: =F2-F4 -> 161.154 | G14: =G2-G4 -> 218.54 | H14: =H2-H4 -> 273.036 | I14: =I2-I4 -> 377.747 | J14: =J2-J4 -> 490.781 | K14: =K2-K4 -> 581.317 | L14: =L2-L4 -> 633.97 | M14: =M2-M4 -> 752.771 | N14: =N2-N4 -> 847.926
A16: (Z-Score Model) | C16: 2004 | D16: 2005 | E16: 2006 | F16: 2007 | G16: 2008 | H16: 2009 | I16: 2010 | J16: 2011 | K16: 2012 | L16: 2013 | M16: 2014 | N16: 2015
A17: Total Assets (TA) | F17: =F2 -> 222.761 | G17: =G2 -> 279.341 | H17: =H2 -> 355.24 | I17: =I2 -> 476.943 | J17: =J2 -> 649.264 | K17: =K2 -> 756.312 | L17: =L2 -> 832.147 | M17: =M2 -> 987.997 | N17: =N2 -> 1158.633
A18: Working Capital | F18: =F14 -> 161.154 | G18: =G14 -> 218.54 | H18: =H14 -> 273.036 | I18: =I14 -> 377.747 | J18: =J14 -> 490.781 | K18: =K14 -> 581.317 | L18: =L14 -> 633.97 | M18: =M14 -> 752.771 | N18: =N14 -> 847.926
A19: WC/TA | F19: =F18/F$17 -> 0.72343902 | G19: =G18/G$17 -> 0.7823413 | H19: =H18/H$17 -> 0.76859588 | I19: =I18/I$17 -> 0.79201708 | J19: =J18/J$17 -> 0.75590361 | K19: =K18/K$17 -> 0.76862062 | L19: =L18/L$17 -> 0.76184857 | M19: =M18/M$17 -> 0.76191628 | N19: =N18/N$17 -> 0.73183312
A20: Retained Earnings | F20: =F8 -> -289.65 | G20: =G8 -> -221.23 | H20: =H8 -> -252.499 | I20: =I8 -> -178.246 | J20: =J8 -> -116.513 | K20: =K8 -> -89.626 | L20: =L8 -> -95.91 | M20: =M8 -> -30.507 | N20: =N8 -> 27.391
A21: RE/TA | F21: =F20/F$17 -> -1.3002725 | G21: =G20/G$17 -> -0.7919711 | H21: =H20/H$17 -> -0.71078426 | I21: =I20/I$17 -> -0.373726 | J21: =J20/J$17 -> -0.17945397 | K21: =K20/K$17 -> -0.118504 | L21: =L20/L$17 -> -0.11525608 | M21: =M20/M$17 -> -0.030877624 | N21: =N20/N$17 -> 0.02364079
A22: EBIT | F22: =F9 -> 32.059 | G22: =G9 -> 21.745 | H22: =H9 -> 36.98 | I22: =I9 -> 98.617 | J22: =J9 -> 101.472 | K22: =K9 -> 124.234 | L22: =L9 -> 161.225 | M22: =M9 -> 193.576 | N22: =N9 -> 188.634
A23: EBIT/TA | F23: =F22/F$17 -> 0.14391657 | G23: =G22/G$17 -> 0.077843926 | H23: =H22/H$17 -> 0.10409864 | I23: =I22/I$17 -> 0.20676894 | J23: =J22/J$17 -> 0.15628774 | K23: =K22/K$17 -> 0.1642629 | L23: =L22/L$17 -> 0.19374582 | M23: =M22/M$17 -> 0.19592772 | N23: =N22/N$17 -> 0.16280738
A24: EBITDA | F24: =F11 -> 209.297 | G24: =G11 -> 225.126 | H24: =H11 -> 233.492 | I24: =I11 -> 303.417 | J24: =J11 -> 362.435 | K24: =K11 -> 417.123 | L24: =L11 -> 498.106 | M24: =M11 -> 578.443 | N24: =N11 -> 640.11
A25: EBITDA/TA | F25: =F24/F$17 -> 0.93955854 | G25: =G24/G$17 -> 0.80591821 | H25: =H24/H$17 -> 0.65727959 | I25: =I24/I$17 -> 0.63617036 | J25: =J24/J$17 -> 0.55822439 | K25: =K24/K$17 -> 0.55152239 | L25: =L24/L$17 -> 0.59857934 | M25: =M24/M$17 -> 0.5854704 | N25: =N24/N$17 -> 0.55247002
A26: Shares Outstanding | F26: =F5 -> 68.642 | G26: =G5 -> 65.633 | H26: =H5 -> 74.568 | I26: =I5 -> 76.39 | J26: =J5 -> 78.776 | K26: =K5 -> 80.611 | L26: =L5 -> 80.583 | M26: =M5 -> 80.205 | N26: =N5 -> 79.5
A27: MV_Equity | F27: =F6 -> 1144.9486 | G27: =G6 -> 574.28875 | H27: =H6 -> 1328.8018 | I27: =I6 -> 1492.6606 | J27: =J6 -> 1868.9606 | K27: =K6 -> 2236.9552 | L27: =L6 -> 4604.5126 | M27: =M6 -> 4484.2616 | N27: =N6 -> 5235.075
A28: BV_TL | F28: =F4 -> 61.607 | G28: =G4 -> 60.801 | H28: =H4 -> 82.204 | I28: =I4 -> 99.196 | J28: =J4 -> 158.483 | K28: =K4 -> 174.995 | L28: =L4 -> 198.177 | M28: =M4 -> 235.226 | N28: =N4 -> 310.707
A29: MV_E/BV_TL | F29: =F27/F28 -> 18.584715 | G29: =G27/G28 -> 9.4453833 | H29: =H27/H28 -> 16.164685 | I29: =I27/I28 -> 15.047589 | J29: =J27/J28 -> 11.792814 | K29: =K27/K28 -> 12.782967 | L29: =L27/L28 -> 23.234344 | M29: =M27/M28 -> 19.063631 | N29: =N27/N28 -> 16.848912
A30: Sales | F30: =F7 -> 284.332 | G30: =G7 -> 303.976 | H30: =H7 -> 312.333 | I30: =I7 -> 387.126 | J30: =J7 -> 479.741 | K30: =K7 -> 560.041 | L30: =L7 -> 660.206 | M30: =M7 -> 761.653 | N30: =N7 -> 845.486
A31: Sales/TA | F31: =F30/F$17 -> 1.2763994 | G31: =G30/G$17 -> 1.0881897 | H31: =H30/H$17 -> 0.87921687 | I31: =I30/I$17 -> 0.8116819 | J31: =J30/J$17 -> 0.73889974 | K31: =K30/K$17 -> 0.74048937 | L31: =L30/L$17 -> 0.79337665 | M31: =M30/M$17 -> 0.77090619 | N31: =N30/N$17 -> 0.72972719
A33: x1 | E33: 1.2 | F33: =F19*$E$33 -> 0.86812683 | G33: =G19*$E$33 -> 0.93880956 | H33: =H19*$E$33 -> 0.92231505 | I33: =I19*$E$33 -> 0.95042049 | J33: =J19*$E$33 -> 0.90708433 | K33: =K19*$E$33 -> 0.92234475 | L33: =L19*$E$33 -> 0.91421828 | M33: =M19*$E$33 -> 0.91429954 | N33: =N19*$E$33 -> 0.87819974
A34: x2 | E34: 1.4 | F34: =$E$34*F21 -> -1.8203815 | G34: =$E$34*G21 -> -1.1087595 | H34: =$E$34*H21 -> -0.99509796 | I34: =$E$34*I21 -> -0.5232164 | J34: =$E$34*J21 -> -0.25123555 | K34: =$E$34*K21 -> -0.16590561 | L34: =$E$34*L21 -> -0.16135851 | M34: =$E$34*M21 -> -0.043228674 | N34: =$E$34*N21 -> 0.033097107
A35: x3 | E35: 3.3 | F35: =$E$35*F23 -> 0.4749247 | G35: =$E$35*G23 -> 0.25688495 | H35: =$E$35*H23 -> 0.3435255 | I35: =$E$35*I23 -> 0.68233751 | J35: =$E$35*J23 -> 0.51574953 | K35: =$E$35*K23 -> 0.54206756 | L35: =$E$35*L23 -> 0.63936119 | M35: =$E$35*M23 -> 0.64656148 | N35: =$E$35*N23 -> 0.53726435
A36: x4 | E36: 0.6 | F36: =$E$36*F29 -> 11.150829 | G36: =$E$36*G29 -> 5.66723 | H36: =$E$36*H29 -> 9.698811 | I36: =$E$36*I29 -> 9.0285532 | J36: =$E$36*J29 -> 7.0756886 | K36: =$E$36*K29 -> 7.66978 | L36: =$E$36*L29 -> 13.940606 | M36: =$E$36*M29 -> 11.438178 | N36: =$E$36*N29 -> 10.109347
A37: x5 | E37: 0.99 | F37: =$E$37*F31 -> 1.2636354 | G37: =$E$37*G31 -> 1.0773078 | H37: =$E$37*H31 -> 0.8704247 | I37: =$E$37*I31 -> 0.80356508 | J37: =$E$37*J31 -> 0.73151074 | K37: =$E$37*K31 -> 0.73308448 | L37: =$E$37*L31 -> 0.78544288 | M37: =$E$37*M31 -> 0.76319713 | N37: =$E$37*N31 -> 0.72242992
A39: Z-Score: | F39: =SUM(F33:F37) -> 11.937135 | G39: =SUM(G33:G37) -> 6.8314728 | H39: =SUM(H33:H37) -> 10.839978 | I39: =SUM(I33:I37) -> 10.94166 | J39: =SUM(J33:J37) -> 8.9787977 | K39: =SUM(K33:K37) -> 9.7013712 | L39: =SUM(L33:L37) -> 16.11827 | M39: =SUM(M33:M37) -> 13.719008 | N39: =SUM(N33:N37) -> 12.280338
A40: z < 1.8 = bad
A41: z > 3 = really good
A42: 1.8 < z < 3.0 = safe
A44: (O-Score Model) | B44: 2003 | C44: 2004 | D44: 2005 | E44: 2006 | F44: 2007 | G44: 2008 | H44: 2009 | I44: 2010 | J44: 2011 | K44: 2012 | L44: 2013 | M44: 2014 | N44: 2015
...

Sheet FRED Graph
A1: FRED Graph Observations
A2: Federal Reserve Economic Data
A3: Link: https://fred.stlouisfed.org
A4: Help: https://fred.stlouisfed.org/help-faq
A5: Economic Research Division
A6: Federal Reserve Bank of St. Louis
A8: Y694RC1A027NBEA | B8: Gross Domestic Product: Research and Development, Billions of Dollars, Annual, Not Seasonally Adjusted
A10: Frequency: Annual
A11: observation_date | B11: Y694RC1A027NBEA
A12: 42005 | B12: 459.3 | C12: =B13 -> 439.6 | D12: =B14 -> 427.7 | E12: =B15 -> 413.5 | F12: =B16 -> 404.1 | G12: =B17 -> 392.1 | H12: =B18 -> 374.8 | I12: =B19 -> 380.5 | J12: =B20 -> 360 | K12: =B21 -> 334.6 | L12: =B22 -> 313.1 | M12: =B23 -> 291.2
A13: 41640 | B13: 439.6
A14: 41275 | B14: 427.7
A15: 40909 | B15: 413.5
A16: 40544 | B16: 404.1
A17: 40179 | B17: 392.1 | F17: 459.3 | G17: 439.6 | H17: 427.7 | I17: 413.5 | J17: 404.1 | K17: 392.1 | L17: 374.8 | M17: 380.5 | N17: 360 | O17: 334.6 | P17: 313.1 | Q17: 291.2
A18: 39814 | B18: 374.8 | F18: 2015 | G18: 2014 | H18: 2013 | I18: 2012 | J18: 2011 | K18: 2010 | L18: 2009 | M18: 2008 | N18: 2007 | O18: 2006 | P18: 2005 | Q18: 2004
A19: 39448 | B19: 380.5
A20: 39083 | B20: 360 | F20: 291.2 | G20: 313.1 | H20: 334.6 | I20: 360 | J20: 380.5 | K20: 378.8 | L20: 392.1 | M20: 404.1 | N20: 413.5 | O20: 427.7 | P20: 439.6 | Q20: 459.3
A21: 38718 | B21: 334.6
A22: 38353 | B22: 313.1
A23: 37987 | B23: 291.2
A24: 37622 | B24: 277.6
A25: 37257 | B25: 265.7
A26: 36892 | B26: 263.2
A27: 36526 | B27: 255.6
A28: 36161 | B28: 237.2
A29: 35796 | B29: 222.4
A30: 35431 | B30: 212
A31: 35065 | B31: 199.8
A32: 34700 | B32: 187.5
... A98: 10594 | B98: 0.3

Sheet gg
A1: EQY_FUND_CRNCY | B1: REL_INDEX | C1: FA_ADJUSTED
A2: USD | C2: ADJUSTED
A3: Ticker | B3: Name | C3: Tkr & Exch | D3: Mkt Cap (USD) | E3: Price:D-1 | F3: Curr Shares Out | G3: Tot Debt:Q | H3: C&CE:Q | I3: EBITDA:Q | J3: EBITDA:Y | K3: Beta:Y-1 | L3: Beta:Y-5 | M3: Beta:Y-2 | N3: Avg | O3: Reg Csh DPS | P3: Dvd P/O:Q | Q3: Dvd P/O:Y | R3: Retntn Rt:Q | S3: Retntn Rt:Y
A4: None (11 securities)
A5: Average | B5: Average | D5: 5289.5446 | E5: 110.67818 | F5: 88.145305 | G5: 895.00818 | H5: 292.73755 | I5: 101.65018 | J5: 357.63597 | K5: 0.97996822 | L5: 0.94502119 | M5: 0.92284829 | N5: =AVERAGE(L5:M5) -> 0.93393474 | O5: 1.3375 | P5: 10.576766 | Q5: 10.20831 | R5: 89.423234 | S5: 89.791689
A6: ALGN US Equity | B6: ALIGN TECHNOLOGY INC | C6: ALGN US | D6: 7820.7179 | E6: 98.139999 | F6: 79.6894 | G6: 0 | H6: 419.948 | I6: 68.98 | J6: 206.638 | K6: 1.1346158 | L6: 1.2034391 | M6: 1.0434969 | N6: =AVERAGE(L6:M6) -> 1.123468 | O6: #N/A N/A | P6: 0 | Q6: 0 | R6: 100 | S6: 100
A7: XRAY US Equity | B7: DENTSPLY SIRONA INC | C7: XRAY US | D7: 13409.538 | E7: 58.080002 | F7: 230.8805 | G7: 1586.2 | H7: 330.7 | I7: 229 | J7: 590.10769 | K7: 0.86219967 | L7: 0.95597805 | M7: 0.89573395 | N7: =AVERAGE(L7:M7) -> 0.925856 | O7: 0.29 | P7: 19.488108 | Q7: 16.16242 | R7: 80.511894 | S7: 83.837578
A8: INGN US Equity | B8: INOGEN INC | C8: INGN US | D8: 1315.5269 | E8: 64.93 | F8: 20.26069 | G8: 0.08 | H8: 86.009 | I8: 8.741 | J8: 29.063 | K8: 1.0324547 | M8: 0.95475526 | N8: =AVERAGE(L8:M8) -> 0.95475526 | O8: #N/A N/A | P8: 0 | Q8: 0 | R8: 100 | S8: 100
A9: ATRI US Equity | B9: ATRION CORPORATION | C9: ATRI US | D9: 894.80934 | E9: 490.5 | F9: 1.82428 | G9: 0 | H9: 23.747 | I9: 13.189 | J9: 53.733 | K9: 0.60018222 | L9: 0.78480538 | M9: 0.66128373 | N9: =AVERAGE(L9:M9) -> 0.72304455 | O9: 3.3 | P9: 25.167456 | Q9: 21.060675 | R9: 74.832542 | S9: 78.939323
A10: HYH US Equity | B10: HALYARD HEALTH INC | C10: HYH US | D10: 1781.0868 | E10: 38.16 | F10: 46.67418 | G10: 589.4 | H10: 86.7 | I10: 56.7 | J10: 220.5 | K10: 1.274704 | M10: 1.0748349 | N10: =AVERAGE(L10:M10) -> 1.0748349 | O10: #N/A N/A | P10: 0 | R10: 100
A11: TFX US Equity | B11: TELEFLEX INC | C11: TFX US | D11: 6803.1417 | E11: 154.42999 | F11: 44.05324 | G11: 1031.862 | H11: 499.459 | I11: 121.466 | J11: 434.995 | K11: 0.88072526 | L11: 0.83720429 | M11: 0.84825644 | N11: =AVERAGE(L11:M11) -> 0.84273037 | O11: 1.36 | P11: 22.6213 | Q11: 23.952942 | R11: 77.3787 | S11: 76.047058
A12: HOLX US Equity | B12: HOLOGIC INC | C12: HOLX US | D12: 10850.419 | E12: 39 | F12: 278.2159 | G12: 3345.4 | H12: 548.4 | I12: 272.8 | J12: 1039.3 | K12: 1.021291 | L12: 0.99125447 | M12: 0.97168927 | N12: =AVERAGE(L12:M12) -> 0.98147187 | O12: #N/A N/A | P12: 0 | Q12: 0 | R12: 100 | S12: 100
